<?xml version="1.0" encoding="utf-8" ?>
<robot name="iiwa">
    <material name="Grey">
        <color rgba="0.7 0.7 0.7 1.0" />
    </material>
    <link name="world" />
    <joint name="world_to_iiwa" type="fixed">
        <origin rpy="0 0 0" xyz="0 0 0" />
        <parent link="world" />
        <child link="iiwa_link_0" />
    </joint>
    <link name="iiwa_link_0">
        
<inertial>
            <origin rpy="0 0 0" xyz="-0.1 0 0.07" />
            <mass value="5" />
            <inertia ixx="0.05" ixy="0" ixz="0" iyy="0.06" iyz="0" izz="0.03" />
        </inertial>

        <visual>
            <origin rpy="0 0 0" xyz="0 0 0" />
            <geometry>
                <mesh filename="package://robots_description/meshes/iiwa/visual/link_0.stl" />
            </geometry>
            <material name="Grey" />
        </visual>
        <collision>
            <origin rpy="0 0 0" xyz="0 0 0" />
            <geometry>
                <mesh filename="package://robots_description/meshes/iiwa/collision/link_0.stl" />
            </geometry>
            <material name="Grey" />
        </collision>
    </link>
    <joint name="iiwa_joint_1" type="revolute">
        <parent link="iiwa_link_0" />
        <child link="iiwa_link_1" />
        <origin rpy="0 0 0" xyz="0 0 0.1575" />
        <axis xyz="0 0 1" />
        <limit effort="300" lower="-2.96705972839" upper="2.96705972839" velocity="1.4835298642" />
        <dynamics damping="20" />
    </joint>
    <link name="iiwa_link_1">
        
<inertial>
            <origin rpy="0 0 0" xyz="0 -0.03 0.12" />
            <mass value="4" />
            <inertia ixx="0.1" ixy="0" ixz="0" iyy="0.09" iyz="0" izz="0.02" />
        </inertial>

        <visual>
            <origin rpy="0 0 0" xyz="0 0 0" />
            <geometry>
                <mesh filename="package://robots_description/meshes/iiwa/visual/link_1.stl" />
            </geometry>
            <material name="Grey" />
        </visual>
        <collision>
            <origin rpy="0 0 0" xyz="0 0 0" />
            <geometry>
                <mesh filename="package://robots_description/meshes/iiwa/collision/link_1.stl" />
            </geometry>
            <material name="Grey" />
        </collision>
    </link>
    <joint name="iiwa_joint_2" type="revolute">
        <parent link="iiwa_link_1" />
        <child link="iiwa_link_2" />
        <origin rpy="1.5707963268   0 3.14159265359" xyz="0 0 0.2025" />
        <axis xyz="0 0 1" />
        <limit effort="300" lower="-2.09439510239" upper="2.09439510239" velocity="1.4835298642" />
        <dynamics damping="20" />
    </joint>
    <link name="iiwa_link_2">
        
<inertial>
            <origin rpy="0 0 0" xyz="0.0003 0.059 0.042" />
            <mass value="4" />
            <inertia ixx="0.05" ixy="0" ixz="0" iyy="0.018" iyz="0" izz="0.044" />
        </inertial>

        <visual>
            <origin rpy="0 0 0" xyz="0 0 0" />
            <geometry>
                <mesh filename="package://robots_description/meshes/iiwa/visual/link_2.stl" />
            </geometry>
            <material name="Grey" />
        </visual>
        <collision>
            <origin rpy="0 0 0" xyz="0 0 0" />
            <geometry>
                <mesh filename="package://robots_description/meshes/iiwa/collision/link_2.stl" />
            </geometry>
            <material name="Grey" />
        </collision>
    </link>
    <joint name="iiwa_joint_3" type="revolute">
        <parent link="iiwa_link_2" />
        <child link="iiwa_link_3" />
        <origin rpy="1.5707963268 0 3.14159265359" xyz="0 0.2045 0" />
        <axis xyz="0 0 1" />
        <limit effort="300" lower="-2.96705972839" upper="2.96705972839" velocity="1.74532925199" />
        <dynamics damping="20" />
    </joint>
    <link name="iiwa_link_3">
        
<inertial>
            <origin rpy="0 0 0" xyz="0 0.03 0.13" />
            <mass value="3" />
            <inertia ixx="0.08" ixy="0" ixz="0" iyy="0.075" iyz="0" izz="0.01" />
        </inertial>

        <visual>
            <origin rpy="0 0 0" xyz="0 0 0" />
            <geometry>
                <mesh filename="package://robots_description/meshes/iiwa/visual/link_3.stl" />
            </geometry>
            <material name="Grey" />
        </visual>
        <collision>
            <origin rpy="0 0 0" xyz="0 0 0" />
            <geometry>
                <mesh filename="package://robots_description/meshes/iiwa/collision/link_3.stl" />
            </geometry>
            <material name="Grey" />
        </collision>
    </link>
    <joint name="iiwa_joint_4" type="revolute">
        <parent link="iiwa_link_3" />
        <child link="iiwa_link_4" />
        <origin rpy="1.5707963268 0 0" xyz="0 0 0.2155" />
        <axis xyz="0 0 1" />
        <limit effort="300" lower="-2.09439510239" upper="2.09439510239" velocity="1.308996939" />
        <dynamics damping="20" />
    </joint>
    <link name="iiwa_link_4">
        
<inertial>
            <origin rpy="0 0 0" xyz="0 0.067 0.034" />
            <mass value="2.7" />
            <inertia ixx="0.03" ixy="0" ixz="0" iyy="0.01" iyz="0" izz="0.029" />
        </inertial>

        <visual>
            <origin rpy="0 0 0" xyz="0 0 0" />
            <geometry>
                <mesh filename="package://robots_description/meshes/iiwa/visual/link_4.stl" />
            </geometry>
            <material name="Grey" />
        </visual>
        <collision>
            <origin rpy="0 0 0" xyz="0 0 0" />
            <geometry>
                <mesh filename="package://robots_description/meshes/iiwa/collision/link_4.stl" />
            </geometry>
            <material name="Grey" />
        </collision>
    </link>
    <joint name="iiwa_joint_5" type="revolute">
        <parent link="iiwa_link_4" />
        <child link="iiwa_link_5" />
        <origin rpy="-1.5707963268 3.14159265359 0" xyz="0 0.1845 0" />
        <axis xyz="0 0 1" />
        <limit effort="300" lower="-2.96705972839" upper="2.96705972839" velocity="2.26892802759" />
        <dynamics damping="20" />
    </joint>
    <link name="iiwa_link_5">
        
<inertial>
            <origin rpy="0 0 0" xyz="0.0001 0.021 0.076" />
            <mass value="1.7" />
            <inertia ixx="0.02" ixy="0" ixz="0" iyy="0.018" iyz="0" izz="0.005" />
        </inertial>

        <visual>
            <origin rpy="0 0 0" xyz="0 0 0" />
            <geometry>
                <mesh filename="package://robots_description/meshes/iiwa/visual/link_5.stl" />
            </geometry>
            <material name="Grey" />
        </visual>
        <collision>
            <origin rpy="0 0 0" xyz="0 0 0" />
            <geometry>
                <mesh filename="package://robots_description/meshes/iiwa/collision/link_5.stl" />
            </geometry>
            <material name="Grey" />
        </collision>
    </link>
    <joint name="iiwa_joint_6" type="revolute">
        <parent link="iiwa_link_5" />
        <child link="iiwa_link_6" />
        <origin rpy="1.5707963268 0 0" xyz="0 0 0.2155" />
        <axis xyz="0 0 1" />
        <limit effort="300" lower="-2.09439510239" upper="2.09439510239" velocity="2.35619449019" />
        <dynamics damping="20" />
    </joint>
    <link name="iiwa_link_6">
        
<inertial>
            <origin rpy="0 0 0" xyz="0 0.0006 0.0004" />
            <mass value="1.8" />
            <inertia ixx="0.005" ixy="0" ixz="0" iyy="0.0036" iyz="0" izz="0.0047" />
        </inertial>

        <visual>
            <origin rpy="0 0 0" xyz="0 0 0" />
            <geometry>
                <mesh filename="package://robots_description/meshes/iiwa/visual/link_6.stl" />
            </geometry>
            <material name="Grey" />
        </visual>
        <collision>
            <origin rpy="0 0 0" xyz="0 0 0" />
            <geometry>
                <mesh filename="package://robots_description/meshes/iiwa/collision/link_6.stl" />
            </geometry>
            <material name="Grey" />
        </collision>
    </link>
    <joint name="iiwa_joint_7" type="revolute">
        <parent link="iiwa_link_6" />
        <child link="iiwa_link_7" />
        <origin rpy="-1.5707963268 3.14159265359 0" xyz="0 0.081 0" />
        <axis xyz="0 0 1" />
        <limit effort="300" lower="-3.05432619099" upper="3.05432619099" velocity="2.35619449019" />
        <dynamics damping="20" />
    </joint>
    <link name="iiwa_link_7">
        
<inertial>
            <origin rpy="0 0 0" xyz="0 0 0.02" />
            <mass value="0.3" />
            <inertia ixx="0.001" ixy="0" ixz="0" iyy="0.001" iyz="0" izz="0.001" />
        </inertial>

        <visual>
            <origin rpy="0 0 0" xyz="0 0 0" />
            <geometry>
                <mesh filename="package://robots_description/meshes/iiwa/visual/link_7.stl" />
            </geometry>
            <material name="Grey" />
        </visual>
        <collision>
            <origin rpy="0 0 0" xyz="0 0 0" />
            <geometry>
                <mesh filename="package://robots_description/meshes/iiwa/collision/link_7.stl" />
            </geometry>
            <material name="Grey" />
        </collision>
    </link>
    <joint name="iiwa_joint_ee" type="fixed">
        <parent link="iiwa_link_7" />
        <child link="iiwa_link_ee" />
        <origin rpy="0 0 0" xyz="0 0 0.045" />
    </joint>
    <link name="iiwa_link_ee" />
    
    <gazebo reference="iiwa_link_0">
        <material>Gazebo/Grey</material>
        <mu1>0.2</mu1>
        <mu2>0.2</mu2>
    </gazebo>
    <gazebo reference="iiwa_link_1">
        <material>Gazebo/Grey</material>
        <mu1>0.2</mu1>
        <mu2>0.2</mu2>
    </gazebo>
    <gazebo reference="iiwa_link_2">
        <material>Gazebo/Grey</material>
        <mu1>0.2</mu1>
        <mu2>0.2</mu2>
    </gazebo>
    <gazebo reference="iiwa_link_3">
        <material>Gazebo/Grey</material>
        <mu1>0.2</mu1>
        <mu2>0.2</mu2>
    </gazebo>
    <gazebo reference="iiwa_link_4">
        <material>Gazebo/Grey</material>
        <mu1>0.2</mu1>
        <mu2>0.2</mu2>
    </gazebo>
    <gazebo reference="iiwa_link_5">
        <material>Gazebo/Grey</material>
        <mu1>0.2</mu1>
        <mu2>0.2</mu2>
    </gazebo>
    <gazebo reference="iiwa_link_6">
        <material>Gazebo/Grey</material>
        <mu1>0.2</mu1>
        <mu2>0.2</mu2>
    </gazebo>
    <gazebo reference="iiwa_link_7">
        <material>Gazebo/Grey</material>
        <mu1>0.2</mu1>
        <mu2>0.2</mu2>
    </gazebo>
    <transmission name="trans_iiwa_joint_1">
        <type>transmission_interface/SimpleTransmission</type>
        <joint name="iiwa_joint_1">
            <hardwareInterface>hardware_interface/PositionJointInterface</hardwareInterface>
        </joint>
        <actuator name="iiwa_joint_1_motor">
            <hardwareInterface>hardware_interface/PositionJointInterface</hardwareInterface>
            <mechanicalReduction>1</mechanicalReduction>
        </actuator>
    </transmission>
    <transmission name="trans_iiwa_joint_2">
        <type>transmission_interface/SimpleTransmission</type>
        <joint name="iiwa_joint_2">
            <hardwareInterface>hardware_interface/PositionJointInterface</hardwareInterface>
        </joint>
        <actuator name="iiwa_joint_2_motor">
            <hardwareInterface>hardware_interface/PositionJointInterface</hardwareInterface>
            <mechanicalReduction>1</mechanicalReduction>
        </actuator>
    </transmission>
    <transmission name="trans_iiwa_joint_3">
        <type>transmission_interface/SimpleTransmission</type>
        <joint name="iiwa_joint_3">
            <hardwareInterface>hardware_interface/PositionJointInterface</hardwareInterface>
        </joint>
        <actuator name="iiwa_joint_3_motor">
            <hardwareInterface>hardware_interface/PositionJointInterface</hardwareInterface>
            <mechanicalReduction>1</mechanicalReduction>
        </actuator>
    </transmission>
    <transmission name="trans_iiwa_joint_4">
        <type>transmission_interface/SimpleTransmission</type>
        <joint name="iiwa_joint_4">
            <hardwareInterface>hardware_interface/PositionJointInterface</hardwareInterface>
        </joint>
        <actuator name="iiwa_joint_4_motor">
            <hardwareInterface>hardware_interface/PositionJointInterface</hardwareInterface>
            <mechanicalReduction>1</mechanicalReduction>
        </actuator>
    </transmission>
    <transmission name="trans_iiwa_joint_5">
        <type>transmission_interface/SimpleTransmission</type>
        <joint name="iiwa_joint_5">
            <hardwareInterface>hardware_interface/PositionJointInterface</hardwareInterface>
        </joint>
        <actuator name="iiwa_joint_5_motor">
            <hardwareInterface>hardware_interface/PositionJointInterface</hardwareInterface>
            <mechanicalReduction>1</mechanicalReduction>
        </actuator>
    </transmission>
    <transmission name="trans_iiwa_joint_6">
        <type>transmission_interface/SimpleTransmission</type>
        <joint name="iiwa_joint_6">
            <hardwareInterface>hardware_interface/PositionJointInterface</hardwareInterface>
        </joint>
        <actuator name="iiwa_joint_6_motor">
            <hardwareInterface>hardware_interface/PositionJointInterface</hardwareInterface>
            <mechanicalReduction>1</mechanicalReduction>
        </actuator>
    </transmission>
    <transmission name="trans_iiwa_joint_7">
        <type>transmission_interface/SimpleTransmission</type>
        <joint name="iiwa_joint_7">
            <hardwareInterface>hardware_interface/PositionJointInterface</hardwareInterface>
        </joint>
        <actuator name="iiwa_joint_7_motor">
            <hardwareInterface>hardware_interface/PositionJointInterface</hardwareInterface>
            <mechanicalReduction>1</mechanicalReduction>
        </actuator>
    </transmission>
    <gazebo>
        <plugin name="gazebo_ros_control" filename="libgazebo_ros_control.so">
            <robotNamespace>/</robotNamespace>
        </plugin>
    </gazebo>
</robot>
